Workbook

Sheet Підсумок
A1: Звірка цін каталогу Majstr з ринком — 25.10.2026
A2: Ціни — тільки робота, ₴. Ринок — відкриті прайси майстрів і компаній та маркетплейси (Київ, Львів, Україна), переважно 2026 р.
A4: Група | B4: Перевірено | C4: В ринку | D4: Підняти | E4: Знизити | F4: Неясно | G4: Аномалій
A5: Плитка і підлоги | B5: =COUNTIFS(Звірка!$A$2:$A$309,A5) -> 68 | C5: =COUNTIFS(Звірка!$A$2:$A$309,$A5,Звірка!$I$2:$I$309,"в ринку") -> 39 | D5: =COUNTIFS(Звірка!$A$2:$A$309,$A5,Звірка!$I$2:$I$309,"підняти") -> 22 | E5: =COUNTIFS(Звірка!$A$2:$A$309,$A5,Звірка!$I$2:$I$309,"знизити") -> 5 | F5: =COUNTIFS(Звірка!$A$2:$A$309,$A5,Звірка!$I$2:$I$309,"неясно") -> 2 | G5: =COUNTIFS(Аномалії!$A$2:$A$131,A5) -> 32
A6: Малярка і гіпсокартон | B6: =COUNTIFS(Звірка!$A$2:$A$309,A6) -> 50 | C6: =COUNTIFS(Звірка!$A$2:$A$309,$A6,Звірка!$I$2:$I$309,"в ринку") -> 29 | D6: =COUNTIFS(Звірка!$A$2:$A$309,$A6,Звірка!$I$2:$I$309,"підняти") -> 14 | E6: =COUNTIFS(Звірка!$A$2:$A$309,$A6,Звірка!$I$2:$I$309,"знизити") -> 6 | F6: =COUNTIFS(Звірка!$A$2:$A$309,$A6,Звірка!$I$2:$I$309,"неясно") -> 1 | G6: =COUNTIFS(Аномалії!$A$2:$A$131,A6) -> 23
A7: Електрика | B7: =COUNTIFS(Звірка!$A$2:$A$309,A7) -> 60 | C7: =COUNTIFS(Звірка!$A$2:$A$309,$A7,Звірка!$I$2:$I$309,"в ринку") -> 27 | D7: =COUNTIFS(Звірка!$A$2:$A$309,$A7,Звірка!$I$2:$I$309,"підняти") -> 13 | E7: =COUNTIFS(Звірка!$A$2:$A$309,$A7,Звірка!$I$2:$I$309,"знизити") -> 17 | F7: =COUNTIFS(Звірка!$A$2:$A$309,$A7,Звірка!$I$2:$I$309,"неясно") -> 3 | G7: =COUNTIFS(Аномалії!$A$2:$A$131,A7) -> 16
A8: Сантехніка | B8: =COUNTIFS(Звірка!$A$2:$A$309,A8) -> 69 | C8: =COUNTIFS(Звірка!$A$2:$A$309,$A8,Звірка!$I$2:$I$309,"в ринку") -> 27 | D8: =COUNTIFS(Звірка!$A$2:$A$309,$A8,Звірка!$I$2:$I$309,"підняти") -> 34 | E8: =COUNTIFS(Звірка!$A$2:$A$309,$A8,Звірка!$I$2:$I$309,"знизити") -> 7 | F8: =COUNTIFS(Звірка!$A$2:$A$309,$A8,Звірка!$I$2:$I$309,"неясно") -> 1 | G8: =COUNTIFS(Аномалії!$A$2:$A$131,A8) -> 24
A9: Будівельник, демонтаж, метал | B9: =COUNTIFS(Звірка!$A$2:$A$309,A9) -> 61 | C9: =COUNTIFS(Звірка!$A$2:$A$309,$A9,Звірка!$I$2:$I$309,"в ринку") -> 21 | D9: =COUNTIFS(Звірка!$A$2:$A$309,$A9,Звірка!$I$2:$I$309,"підняти") -> 32 | E9: =COUNTIFS(Звірка!$A$2:$A$309,$A9,Звірка!$I$2:$I$309,"знизити") -> 5 | F9: =COUNTIFS(Звірка!$A$2:$A$309,$A9,Звірка!$I$2:$I$309,"неясно") -> 3 | G9: =COUNTIFS(Аномалії!$A$2:$A$131,A9) -> 35
A10: Разом | B10: =SUM(B5:B9) -> 308 | C10: =SUM(C5:C9) -> 143 | D10: =SUM(D5:D9) -> 115 | E10: =SUM(E5:E9) -> 40 | F10: =SUM(F5:F9) -> 10 | G10: =SUM(G5:G9) -> 130
A11: Нових позицій запропоновано | B11: =COUNTA('Нові позиції'!$C$2:$C$64) -> 63
A12: Рішень уже прийнято (Звірка) | B12: =COUNTA(Звірка!$L$2:$L$309) -> 0
A14: Як користуватись:
A15: • «Звірка»: у жовтій колонці «Рішення» обери Прийняти / Відхилити / Своя ціна (тоді впиши її поруч). «Підсумкова ціна» порахується сама — цей стовпчик і піде в міграцію.
A16: • «Аномалії»: помилки одиниць, дублікати з різними цінами, нулі, «заглушки» (однакова ціна на різні роботи).
A17: • «Нові позиції»: що часто є в прайсах майстрів, а в нас немає. Постав «Так» і ціну — додамо.
A18: • Порожні жовті клітинки = рішення ще не прийняте; така позиція лишається за нашою ціною.
A19: Важливо: stroyremdizayn.kiev.ua і demontazh-pro.kiev.ua збігаються з нашим каталогом майже 1:1 — схоже, звідти колись брали ціни. Аудитори не рахували їх незалежними джерелами.
A20: Чужі бази цін кошторисних застосунків (напр. lihtar.app) не використовувались.

Sheet Звірка
A1: Група | B1: Фах | C1: Позиція | D1: Од. | E1: Наша ціна, ₴ | F1: Ринок мін, ₴ | G1: Ринок медіана, ₴ | H1: Ринок макс, ₴ | I1: Вердикт | J1: Пропонована ціна, ₴ | K1: Зміна, % | L1: Рішення | M1: Своя ціна, ₴ | N1: Підсумкова ціна, ₴ | O1: Примітка аудитора | P1: Джерела (URL · що написано · місто · дата)
A2: Плитка і підлоги | B2: Підлоги | C2: Демонтаж лінолеуму ковроліну | D2: м² | E2: 20 | F2: 80 | G2: 130 | H2: 250 | I2: підняти | J2: 100 | K2: =IF(AND(ISNUMBER(J2),E2>0),J2/E2-1,"") -> 4 | N2: =IF(L2="Своя ціна",M2,IF(L2="Прийняти",IF(ISNUMBER(J2),J2,E2),E2)) -> 20 | O2: 20 грн/м² явно замало. Медіана 130; пропоновано 100 (лінолеум без клею). | P2: https://rbk-alba.com/ua/price · лінолеум 250 / на клей 300 · не вказано · 19.10.2026 https://kabanchik.ua/ua/kyiv/category/ukladannia-laminatu · демонтаж старого покриття 130 · Київ · 10.2026 https://rating-remont-kvartir.com.ua/ua/rozcinki-na-roboti-z-pidlogami-lviv/ · демонтаж покриття 60–100 · Львів · 07.01.2026
A3: Плитка і підлоги | B3: Підлоги | C3: Машинна стяжка самовирівнююча | D3: м² | E3: 301 | F3: 350 | G3: 362 | H3: 373 | I3: підняти | J3: 350 | K3: =IF(AND(ISNUMBER(J3),E3>0),J3/E3-1,"") -> 0.1627907 | N3: =IF(L3="Своя ціна",M3,IF(L3="Прийняти",IF(ISNUMBER(J3),J3,E3),E3)) -> 301 | O3: Наша ціна нижча навіть за мінімум rabotniki (307). | P3: https://www.rabotniki.ua/uk/chernovye-raboty-po-polu/kiev · машинна самовирівнююча 307/373/400 грн/м² · Київ · 2026 https://mirafloor.com.ua/statti/nalivna-pidloga-tsina-za-m2.html · наливна від 350 · Київ · 09.2026
A4: Плитка і підлоги | B4: Підлоги | C4: Монтаж алюмінієвого плінтуса | D4: м.п. | E4: 312 | F4: 350 | G4: 375 | H4: 400 | I4: підняти | J4: 370 | K4: =IF(AND(ISNUMBER(J4),E4>0),J4/E4-1,"") -> 0.18589744 | N4: =IF(L4="Своя ціна",M4,IF(L4="Прийняти",IF(ISNUMBER(J4),J4,E4),E4)) -> 312 | P4: https://stroyremdizayn.kiev.ua/rascenki-na-otdelochnye-raboty.html · алюмінієвий 400 · Київ · 2026 https://bud.arsel.com.ua/tsiny-na-budivelni-roboty/ · алюмінієвий 350 · Київ і обл. · 01.01.2026
A5: Плитка і підлоги | B5: Підлоги | C5: Настил лінолеуму ковроліну на клей | D5: м² | E5: 200 | F5: 220 | G5: 260 | H5: 300 | I5: підняти | J5: 260 | K5: =IF(AND(ISNUMBER(J5),E5>0),J5/E5-1,"") -> 0.3 | N5: =IF(L5="Своя ціна",M5,IF(L5="Прийняти",IF(ISNUMBER(J5),J5,E5),E5)) -> 200 | O5: Зараз дорівнює варіанту без клею (200), хоча на клей має бути дорожче. | P5: https://stroyremdizayn.kiev.ua/rascenki-na-otdelochnye-raboty.html · на клей 300 · Київ · 2026 https://bud.arsel.com.ua/tsiny-na-budivelni-roboty/ · лінолеум на клей 220 · Київ і обл. · 01.01.2026
A6: Плитка і підлоги | B6: Підлоги | C6: Настилання підлоги з дошки по лагах | D6: м² | E6: 400 | F6: 441 | G6: 452 | H6: 460 | I6: підняти | J6: 450 | K6: =IF(AND(ISNUMBER(J6),E6>0),J6/E6-1,"") -> 0.125 | N6: =IF(L6="Своя ціна",M6,IF(L6="Прийняти",IF(ISNUMBER(J6),J6,E6),E6)) -> 400 | P6: https://www.rabotniki.ua/uk/price/ukladka-laminata-price/kiev · дерев'яна підлога у шпунт 441 · Київ · 25.10.2026 https://www.rabotniki.ua/uk/price/tsiklevanie-parketa-pokrytie-lakom · 452 · Україна (агрегат) · 25.10.2026 https://stroyremdizayn.kiev.ua/rascenki-na-otdelochnye-raboty.html · підлога з дошки 460 · Київ · 2026
A7: Плитка і підлоги | B7: Підлоги | C7: Укладання паркетної / інженерної дошки плаваючим способом | D7: м² | E7: 420 | F7: 435 | G7: 485 | H7: 491 | I7: підняти | J7: 480 | K7: =IF(AND(ISNUMBER(J7),E7>0),J7/E7-1,"") -> 0.14285714 | N7: =IF(L7="Своя ціна",M7,IF(L7="Прийняти",IF(ISNUMBER(J7),J7,E7),E7)) -> 420 | O7: Наша ціна нижча за всі три джерела. | P7: https://www.rabotniki.ua/uk/price/ukladka-laminata-price/kiev · Київ, тришарова 491 · Київ · 25.10.2026 https://www.rabotniki.ua/uk/price/tsiklevanie-parketa-pokrytie-lakom · тришарова (Україна) 485 · Україна (агрегат) · 25.10.2026 https://bud.arsel.com.ua/tsiny-na-budivelni-roboty/ · тришарова 435 · Київ і обл. · 01.01.2026
A8: Плитка і підлоги | B8: Плитка | C8: Виріз отворів до 70 мм | D8: шт | E8: 196 | F8: 150 | G8: 240 | H8: 300 | I8: підняти | J8: 240 | K8: =IF(AND(ISNUMBER(J8),E8>0),J8/E8-1,"") -> 0.2244898 | N8: =IF(L8="Своя ціна",M8,IF(L8="Прийняти",IF(ISNUMBER(J8),J8,E8),E8)) -> 196 | P8: https://www.rabotniki.ua/uk/plitochnye-raboty · 150/273/400 грн/шт · Україна (агрегат) · 2026 https://www.rabotniki.ua/uk/price/ukladka-plitki-na-pol/kiev · сер. 295 · Київ · 25.10.2026 https://kabanchik.ua/ua/kyiv/category/ukladannia-plytky · 240 · Київ · 10.2026 https://plitochnik.kiev.ua/ua/%D0%B2%D0%B0%D1%80%D1%82%D1%96%D1%81%D1%82%D1%8C-%D1%80%D0%BE%D0%B1%D1%96%D1%82-%D0%BF%D0%BB%D0%B8%D1%82%D0%BE%D1%87%D0%BD%D0%B8%D0%BA%D0%B0.html · до 70 мм 204 · Київ · 2026 https://bud.arsel.com.ua/tsiny-na-budivelni-roboty/ · 220 · Київ і обл. · 01.01.2026 https://liv-comfort.kyiv.ua/price-remont/index.html · 250 · Київ · 2026 https://stroyremdizayn.kiev.ua/rascenki-na-otdelochnye-raboty.html · 300 · Київ · 2026 https://remmo.lviv.ua/plytochni-roboty-lviv/ · 200 · Львів · 25.01.2026 https://plitka.ua/ua/services/ukladannya-plitki/ · до 70 мм 150 (2025) · Київ · 2025 https://24tv.ua/skilki-naspravdi-koshtuye-poklasti-plitku-vanniy-realni-tsini_n3111316 · 250 · не вказано · 24.07.2026 https://www.remonthub.org/prices.php · 220 · Київ · 2026
A9: Плитка і підлоги | B9: Плитка | C9: Запил плитки під 45° | D9: м.п. | E9: 367 | F9: 300 | G9: 463 | H9: 550 | I9: підняти | J9: 460 | K9: =IF(AND(ISNUMBER(J9),E9>0),J9/E9-1,"") -> 0.25340599 | N9: =IF(L9="Своя ціна",M9,IF(L9="Прийняти",IF(ISNUMBER(J9),J9,E9),E9)) -> 367 | P9: https://www.rabotniki.ua/uk/plitochnye-raboty · 250/478/750 грн/м.п. · Україна (агрегат) · 2026 https://www.rabotniki.ua/uk/price/ukladka-plitki-na-pol/kiev · сер. 484 · Київ · 25.10.2026 https://www.rabotniki.ua/uk/plitochnye-raboty/lvov · 250/463/700 · Львів · 2026 https://budver.com/masters/zapil-ta-shlifuvannya-kromok-plitki-pid-45-gradusiv · 275/550/825 · Україна (агрегат) · 2026 https://kabanchik.ua/ua/kyiv/category/ukladannia-plytky · 420 · Київ · 10.2026 https://plitochnik.kiev.ua/ua/%D0%B2%D0%B0%D1%80%D1%82%D1%96%D1%81%D1%82%D1%8C-%D1%80%D0%BE%D0%B1%D1%96%D1%82-%D0%BF%D0%BB%D0%B8%D1%82%D0%BE%D1%87%D0%BD%D0%B8%D0%BA%D0%B0.html · 420 · Київ · 2026 https://bud.arsel.com.ua/tsiny-na-budivelni-roboty/ · 425 · Київ і обл. · 01.01.2026 https://liv-comfort.kyiv.ua/price-remont/index.html · 500 · Київ · 2026 https://stroyremdizayn.kiev.ua/rascenki-na-otdelochnye-raboty.html · 500 · Київ · 2026 https://remmo.lviv.ua/plytochni-roboty-lviv/ · 300 · Львів · 25.01.2026 https://plitka.ua/ua/services/ukladannya-plitki/ · 300 (2025) · Київ · 2025
A10: Плитка і підлоги | B10: Плитка | C10: Заповнення швів герметиком | D10: м.п. | E10: 130 | F10: 100 | G10: 228 | H10: 250 | I10: підняти | J10: 220 | K10: =IF(AND(ISNUMBER(J10),E10>0),J10/E10-1,"") -> 0.69230769 | N10: =IF(L10="Своя ціна",M10,IF(L10="Прийняти",IF(ISNUMBER(J10),J10,E10),E10)) -> 130 | O10: Після підвищення 'Заміна силіконового шва' (180) треба тримати вище за просте заповнення, ~280. | P10: https://www.rabotniki.ua/uk/plitochnye-raboty · герметична 150/215/350 грн/м.п. · Україна (агрегат) · 2026 https://plitochnik.kiev.ua/ua/%D0%B2%D0%B0%D1%80%D1%82%D1%96%D1%81%D1%82%D1%8C-%D1%80%D0%BE%D0%B1%D1%96%D1%82-%D0%BF%D0%BB%D0%B8%D1%82%D0%BE%D1%87%D0%BD%D0%B8%D0%BA%D0%B0.html · герметизація шва 240 грн/м.п. · Київ · 2026 https://kabanchik.ua/ua/kyiv/category/ukladannia-plytky · герметизація швів від 110 · Київ · 10.2026 https://stroyremdizayn.kiev.ua/rascenki-na-otdelochnye-raboty.html · герметик 250 грн/м.п. · Київ · 2026 https://plitka.ua/ua/services/ukladannya-plitki/ · герметик у шви 100 грн/м.п. (2025) · Київ · 2025 https://24tv.ua/skilki-naspravdi-koshtuye-poklasti-plitku-vanniy-realni-tsini_n3111316 · силікон у кутах 250 грн/м.п. · не вказано · 24.07.2026
A11: Плитка і підлоги | B11: Плитка | C11: Заповнення швів епоксидною сумішшю | D11: м² | E11: 241 | F11: 200 | G11: 290 | H11: 369 | I11: підняти | J11: 290 | K11: =IF(AND(ISNUMBER(J11),E11>0),J11/E11-1,"") -> 0.2033195 | N11: =IF(L11="Своя ціна",M11,IF(L11="Прийняти",IF(ISNUMBER(J11),J11,E11),E11)) -> 241 | O11: rabotniki (315) і arsel (320) вказують у грн/м.п. — розбіжність одиниць, не враховано. | P11: https://budver.com/masters/zatirannya-shviv-plitki-epoksidnoyu-zatirkoyu · 187/369/550 грн/м² · Україна (агрегат) · 2026 https://plitochnik.kiev.ua/ua/%D0%B2%D0%B0%D1%80%D1%82%D1%96%D1%81%D1%82%D1%8C-%D1%80%D0%BE%D0%B1%D1%96%D1%82-%D0%BF%D0%BB%D0%B8%D1%82%D0%BE%D1%87%D0%BD%D0%B8%D0%BA%D0%B0.html · 300 грн/м² · Київ · 2026 https://plitochnik.kiev.ua/ua/%D1%83%D0%BA%D0%BB%D0%B0%D0%B4%D0%B0%D0%BD%D0%BD%D1%8F-%D1%84%D0%BE%D1%80%D0%BC%D0%B0%D1%82%D0%BD%D0%BE%D0%B3%D0%BE-%D0%BA%D0%B5%D1%80%D0%B0%D0%BC%D0%BE%D0%B3%D1%80%D0%B0%D0%BD%D1%96%D1%82%D0%B0.html · 240 грн/м² · Київ · 2026 https://24tv.ua/skilki-naspravdi-koshtuye-poklasti-plitku-vanniy-realni-tsini_n3111316 · 320 грн/м² · не вказано · 24.07.2026 https://www.remonthub.org/prices.php · 290 грн/м² · Київ · 2026 https://plitka.ua/ua/services/ukladannya-plitki/ · 200 грн/м² (2025) · Київ · 2025 https://liv-comfort.kyiv.ua/price-remont/index.html · двокомпонентна 250 · Київ · 2026
A12: Плитка і підлоги | B12: Плитка | C12: Заповнення швів цементною сумішшю | D12: м² | E12: 116 | F12: 50 | G12: 173 | H12: 200 | I12: підняти | J12: 170 | K12: =IF(AND(ISNUMBER(J12),E12>0),J12/E12-1,"") -> 0.46551724 | N12: =IF(L12="Своя ціна",M12,IF(L12="Прийняти",IF(ISNUMBER(J12),J12,E12),E12)) -> 116 | O12: SR вказує 50 грн/м.п. — інша одиниця, не враховано. | P12: https://www.rabotniki.ua/uk/plitochnye-raboty · стандартна 100/166/250 грн/м² · Україна (агрегат) · 2026 https://www.rabotniki.ua/uk/price/ukladka-plitki-na-pol/kiev · сер. 182 · Київ · 25.10.2026 https://www.rabotniki.ua/uk/plitochnye-raboty/lvov · 140/163/200 · Львів · 2026 https://budver.com/masters/zatirannya-shviv-plitki · 110/193/275 · Україна (агрегат) · 2026 https://kabanchik.ua/ua/kyiv/category/ukladannia-plytky · 140 грн/м² · Київ · 10.2026 https://plitochnik.kiev.ua/ua/%D0%B2%D0%B0%D1%80%D1%82%D1%96%D1%81%D1%82%D1%8C-%D1%80%D0%BE%D0%B1%D1%96%D1%82-%D0%BF%D0%BB%D0%B8%D1%82%D0%BE%D1%87%D0%BD%D0%B8%D0%BA%D0%B0.html · до 5 мм 180 грн/м² · Київ · 2026 https://bud.arsel.com.ua/tsiny-na-budivelni-roboty/ · 120 грн/м² · Київ і обл. · 01.01.2026 https://www.remonthub.org/prices.php · 200 грн/м² · Київ · 2026 https://24tv.ua/skilki-naspravdi-koshtuye-poklasti-plitku-vanniy-realni-tsini_n3111316 · 200 грн/м² · не вказано · 24.07.2026 https://remmo.lviv.ua/plytochni-roboty-lviv/ · 50 грн/м² · Львів · 25.01.2026
A13: Плитка і підлоги | B13: Плитка | C13: Стяжка маякова цементна | D13: м² | E13: 342 | F13: 350 | G13: 400 | H13: 500 | I13: підняти | J13: 400 | K13: =IF(AND(ISNUMBER(J13),E13>0),J13/E13-1,"") -> 0.16959064 | N13: =IF(L13="Своя ціна",M13,IF(L13="Прийняти",IF(ISNUMBER(J13),J13,E13),E13)) -> 342 | O13: Дубль FLOORING 'Цементно-піщана стяжка понад 20м2' = 400. Варто вирівняти. | P13: https://www.rabotniki.ua/uk/chernovye-raboty-po-polu/kiev · ЦПС до 5 см 250/396/600 грн/м² · Київ · 2026 https://bud.arsel.com.ua/tsiny-na-budivelni-roboty/ · до 5 см 350 · Київ і обл. · 01.01.2026 https://rbk-alba.com/ua/price · до 5 см 450 · не вказано · 19.10.2026 https://plitochnik.kiev.ua/ua/%D0%B2%D0%B0%D1%80%D1%82%D1%96%D1%81%D1%82%D1%8C-%D1%80%D0%BE%D0%B1%D1%96%D1%82-%D0%BF%D0%BB%D0%B8%D1%82%D0%BE%D1%87%D0%BD%D0%B8%D0%BA%D0%B0.html · до 50 мм 480 · Київ · 2026 https://liv-comfort.kyiv.ua/price-remont/index.html · до 50 мм 400 · Київ · 2026 https://stroyremdizayn.kiev.ua/rascenki-na-otdelochnye-raboty.html · понад 20 м² 360 · Київ · 2026 https://www.remonthub.org/prices.php · до 5 см 500 · Київ · 2026
A14: Плитка і підлоги | B14: Плитка | C14: Укладання декоративної плитки під «цеглу» або «камінь» (гіпсова, бетонна) | D14: м² | E14: 0 | F14: 660 | G14: 1022 | H14: 1105 | I14: підняти | J14: 1000 | K14: =IF(AND(ISNUMBER(J14),E14>0),J14/E14-1,"") | N14: =IF(L14="Своя ціна",M14,IF(L14="Прийняти",IF(ISNUMBER(J14),J14,E14),E14)) -> 0 | O14: Ціна 0 — пропущене значення. | P14: https://www.rabotniki.ua/uk/plitochnye-raboty · декоративна гіпсова плитка 600/1105/1650 грн/м² · Україна (агрегат) · 2026 https://www.rabotniki.ua/uk/plitochnye-raboty · гіпсова цеглинка 600/1022/1500 · Україна (агрегат) · 2026 https://kabanchik.ua/ua/kyiv/category/ukladannia-plytky · декоративна гіпсова плитка 1060 грн/м² · Київ · 10.2026 https://budver.com/masters/plitochni-roboti · гіпсова плитка від 660 · Україна (ціни 'від') · 2026 https://stroyremdizayn.kiev.ua/rascenki-na-otdelochnye-raboty.html · декоративна цегла/камінь 1000 · Київ · 2026
A15: Плитка і підлоги | B15: Плитка | C15: Укладання керамічного паркету, дрібної дошки | D15: м² | E15: 866 | F15: 800 | G15: 1012 | H15: 1267 | I15: підняти | J15: 1000 | K15: =IF(AND(ISNUMBER(J15),E15>0),J15/E15-1,"") -> 0.15473441 | N15: =IF(L15="Своя ціна",M15,IF(L15="Прийняти",IF(ISNUMBER(J15),J15,E15),E15)) -> 866 | P15: https://plitochnik.kiev.ua/ua/%D0%B2%D0%B0%D1%80%D1%82%D1%96%D1%81%D1%82%D1%8C-%D1%80%D0%BE%D0%B1%D1%96%D1%82-%D0%BF%D0%BB%D0%B8%D1%82%D0%BE%D1%87%D0%BD%D0%B8%D0%BA%D0%B0.html · дрібний керамічний паркет 1200 грн/м² · Київ · 2026 https://plitka.ua/ua/services/ukladannya-plitki/ · керамопаркет 800 грн/м² (2025) · Київ · 2025 https://www.rabotniki.ua/uk/plitochnye-raboty · керамічний паркет до 1200 мм 750/1267/1810 грн/м² · Україна (агрегат) · 2026 https://budver.com/masters/plitochni-roboti · керамічний паркет від 825 грн/м² · Україна (ціни 'від') · 2026
A16: Плитка і підлоги | B16: Плитка | C16: Укладання клінкерної підлогової плитки | D16: м² | E16: 891 | F16: 770 | G16: 1080 | H16: 1244 | I16: підняти | J16: 1100 | K16: =IF(AND(ISNUMBER(J16),E16>0),J16/E16-1,"") -> 0.2345679 | N16: =IF(L16="Своя ціна",M16,IF(L16="Прийняти",IF(ISNUMBER(J16),J16,E16),E16)) -> 891 | O16: Позиція в категорії 'Облицювання сходів'. | P16: https://www.rabotniki.ua/uk/plitochnye-raboty · клінкер 700/1244/2000 грн/м² · Україна (агрегат) · 2026 https://budver.com/masters/plitochni-roboti · клінкер від 770 · Україна (ціни 'від') · 2026 https://plitochnik.kiev.ua/ua/%D0%B2%D0%B0%D1%80%D1%82%D1%96%D1%81%D1%82%D1%8C-%D1%80%D0%BE%D0%B1%D1%96%D1%82-%D0%BF%D0%BB%D0%B8%D1%82%D0%BE%D1%87%D0%BD%D0%B8%D0%BA%D0%B0.html · промисловий клінкер 1080 · Київ · 2026 https://stroyremdizayn.kiev.ua/rascenki-na-otdelochnye-raboty.html · клінкер 1200 · Київ · 2026 https://remmo.lviv.ua/plytochni-roboty-lviv/ · клінкер від 1000 · Львів · 25.01.2026
A17: Плитка і підлоги | B17: Плитка | C17: Укладання плитки 1200х1200 мм | D17: м² | E17: 1130 | F17: 1250 | G17: 1345 | H17: 1440 | I17: підняти | J17: 1300 | K17: =IF(AND(ISNUMBER(J17),E17>0),J17/E17-1,"") -> 0.15044248 | N17: =IF(L17="Своя ціна",M17,IF(L17="Прийняти",IF(ISNUMBER(J17),J17,E17),E17)) -> 1130 | P17: https://plitochnik.kiev.ua/ua/%D1%83%D0%BA%D0%BB%D0%B0%D0%B4%D0%B0%D0%BD%D0%BD%D1%8F-%D1%84%D0%BE%D1%80%D0%BC%D0%B0%D1%82%D0%BD%D0%BE%D0%B3%D0%BE-%D0%BA%D0%B5%D1%80%D0%B0%D0%BC%D0%BE%D0%B3%D1%80%D0%B0%D0%BD%D1%96%D1%82%D0%B0.html · 1200×1200 1440 грн/м² · Київ · 2026 https://stroyremdizayn.kiev.ua/rascenki-na-otdelochnye-raboty.html · 1200×1200 1250 грн/м² · Київ · 2026
A18: Плитка і підлоги | B18: Плитка | C18: Укладання плитки 300х300 | D18: м² | E18: 641 | F18: 500 | G18: 820 | H18: 985 | I18: підняти | J18: 800 | K18: =IF(AND(ISNUMBER(J18),E18>0),J18/E18-1,"") -> 0.24804992 | N18: =IF(L18="Своя ціна",M18,IF(L18="Прийняти",IF(ISNUMBER(J18),J18,E18),E18)) -> 641 | O18: Окремої ціни на 300х300 мало; порівняно з базовою ціною укладання на підлогу/стіни. | P18: https://plitka.ua/ua/services/ukladannya-plitki/ · 300х300 500 грн/м² (2025) · Київ · 2025 https://plitochnik.kiev.ua/ua/%D0%B2%D0%B0%D1%80%D1%82%D1%96%D1%81%D1%82%D1%8C-%D1%80%D0%BE%D0%B1%D1%96%D1%82-%D0%BF%D0%BB%D0%B8%D1%82%D0%BE%D1%87%D0%BD%D0%B8%D0%BA%D0%B0.html · кераміка до 600 мм 720 грн/м² · Київ · 2026 https://www.rabotniki.ua/uk/price/ukladka-plitki-na-pol/kiev · підлога сер. 985 грн/м² · Київ · 25.10.2026 https://www.rabotniki.ua/uk/plitochnye-raboty · підлога сер. 905 · Україна (агрегат) · 2026 https://kabanchik.ua/ua/kyiv/category/ukladannia-plytky · підлога 820 · Київ · 10.2026 https://bud.arsel.com.ua/tsiny-na-budivelni-roboty/ · підлога 900 · Київ і обл. · 01.01.2026 https://liv-comfort.kyiv.ua/price-remont/index.html · підлога 750 · Київ · 2026
A19: Плитка і підлоги | B19: Плитка | C19: Укладання плитки 300х600 | D19: м² | E19: 594 | F19: 500 | G19: 850 | H19: 1033 | I19: підняти | J19: 850 | K19: =IF(AND(ISNUMBER(J19),E19>0),J19/E19-1,"") -> 0.43097643 | N19: =IF(L19="Своя ціна",M19,IF(L19="Прийняти",IF(ISNUMBER(J19),J19,E19),E19)) -> 594 | O19: Типовий настінний формат; ринок 700–1000 у більшості джерел. Наші 594 — на рівні мінімумів. | P19: https://www.rabotniki.ua/uk/plitochnye-raboty · стіни 500/933/1550 грн/м² · Україна (агрегат) · 2026 https://www.rabotniki.ua/uk/price/ukladka-plitki-na-pol/kiev · стіни сер. 1033 грн/м² · Київ · 25.10.2026 https://www.rabotniki.ua/uk/plitochnye-raboty/lvov · стіни 750/963/1300 грн/м² · Львів · 2026 https://kabanchik.ua/ua/kyiv/category/ukladannia-plytky · стіни (проста укладка) 840 грн/м² · Київ · 10.2026 https://plitochnik.kiev.ua/ua/%D0%B2%D0%B0%D1%80%D1%82%D1%96%D1%81%D1%82%D1%8C-%D1%80%D0%BE%D0%B1%D1%96%D1%82-%D0%BF%D0%BB%D0%B8%D1%82%D0%BE%D1%87%D0%BD%D0%B8%D0%BA%D0%B0.html · керамічна плитка до 600 мм 720 грн/м² · Київ · 2026 https://plitka.ua/ua/services/ukladannya-plitki/ · 300х600 500 грн/м² (2025) · Київ · 2025 https://bud.arsel.com.ua/tsiny-na-budivelni-roboty/ · плитка на стіни 900 грн/м² · Київ і обл. · 01.01.2026 https://liv-comfort.kyiv.ua/price-remont/index.html · плитка стіни/укоси 850 грн/м² · Київ · 2026 https://remmo.lviv.ua/plytochni-roboty-lviv/ · укладання плитки на стіни 700 грн/м² · Львів · 25.01.2026 https://www.remonthub.org/prices.php · укладка плитки 850 грн/м² · Київ · 2026 https://stroyremdizayn.kiev.ua/rascenki-na-otdelochnye-raboty.html · керамічна плитка 850 грн/м² · Київ · 2026
A20: Плитка і підлоги | B20: Плитка | C20: Укладання плитки 600х1200 | D20: м² | E20: 732 | F20: 800 | G20: 876 | H20: 950 | I20: підняти | J20: 880 | K20: =IF(AND(ISNUMBER(J20),E20>0),J20/E20-1,"") -> 0.20218579 | N20: =IF(L20="Своя ціна",M20,IF(L20="Прийняти",IF(ISNUMBER(J20),J20,E20),E20)) -> 732 | O20: DF: доплата за великий формат +20–30% (Київ) до базової 800–1400. | P20: https://plitka.ua/ua/services/ukladannya-plitki/ · 600х1200 800 грн/м² (2025) · Київ · 2025 https://stroyremdizayn.kiev.ua/rascenki-na-otdelochnye-raboty.html · 1200×600 950 грн/м² · Київ · 2026 https://plitochnik.kiev.ua/ua/%D0%B2%D0%B0%D1%80%D1%82%D1%96%D1%81%D1%82%D1%8C-%D1%80%D0%BE%D0%B1%D1%96%D1%82-%D0%BF%D0%BB%D0%B8%D1%82%D0%BE%D1%87%D0%BD%D0%B8%D0%BA%D0%B0.html · середній формат від 816 грн/м² · Київ · 2026 https://plitochnik.kiev.ua/ua/%D0%B2%D0%B0%D1%80%D1%82%D1%96%D1%81%D1%82%D1%8C-%D1%80%D0%BE%D0%B1%D1%96%D1%82-%D0%BF%D0%BB%D0%B8%D1%82%D0%BE%D1%87%D0%BD%D0%B8%D0%BA%D0%B0.html · великий формат від 936 грн/м² · Київ · 2026
A21: Плитка і підлоги | B21: Плитка | C21: Укладання плитки 600х600 | D21: м² | E21: 631 | F21: 600 | G21: 835 | H21: 985 | I21: підняти | J21: 830 | K21: =IF(AND(ISNUMBER(J21),E21>0),J21/E21-1,"") -> 0.31537242 | N21: =IF(L21="Своя ціна",M21,IF(L21="Прийняти",IF(ISNUMBER(J21),J21,E21),E21)) -> 631 | O21: Базовий формат підлоги. Наша ціна нижча за всі джерела, крім plitka.ua (2025). DF: Київ 800–1400, Львів 550–800, інші міста 450–900. | P21: https://www.rabotniki.ua/uk/price/ukladka-plitki-na-pol/kiev · укладання плитки на підлогу: 550/985/1500 грн/м² (мін/сер/макс) · Київ · 25.10.2026 https://www.rabotniki.ua/uk/plitochnye-raboty/lvov · підлога 550/888/1300 грн/м² · Львів · 2026 https://www.rabotniki.ua/uk/plitochnye-raboty · підлога 500/905/1500 грн/м² · Україна (агрегат) · 2026 https://kabanchik.ua/ua/kyiv/category/ukladannia-plytky · укладання плитки на підлогу 820 грн/м² (блок 'Вартість послуг') · Київ · 10.2026 https://plitochnik.kiev.ua/ua/%D0%B2%D0%B0%D1%80%D1%82%D1%96%D1%81%D1%82%D1%8C-%D1%80%D0%BE%D0%B1%D1%96%D1%82-%D0%BF%D0%BB%D0%B8%D1%82%D0%BE%D1%87%D0%BD%D0%B8%D0%BA%D0%B0.html · керамограніт до 600 мм 744 грн/м² · Київ · 2026 https://stroyremdizayn.kiev.ua/rascenki-na-otdelochnye-raboty.html · 600х600 850 грн/м² · Київ · 2026 https://plitka.ua/ua/services/ukladannya-plitki/ · 600х600 600 грн/м² (2025) · Київ · 2025 https://bud.arsel.com.ua/tsiny-na-budivelni-roboty/ · плитка на підлогу 900 грн/м² · Київ і обл. · 01.01.2026 https://liv-comfort.kyiv.ua/price-remont/index.html · плитка підлога 750 грн/м² · Київ · 2026 https://remmo.lviv.ua/plytochni-roboty-lviv/ · керамограніт від 700 грн/м² · Львів · 25.01.2026
A22: Плитка і підлоги | B22: Плитка | C22: Укладання плитки 800х800 | D22: м² | E22: 779 | F22: 816 | G22: 900 | H22: 950 | I22: підняти | J22: 900 | K22: =IF(AND(ISNUMBER(J22),E22>0),J22/E22-1,"") -> 0.15532734 | N22: =IF(L22="Своя ціна",M22,IF(L22="Прийняти",IF(ISNUMBER(J22),J22,E22),E22)) -> 779 | P22: https://stroyremdizayn.kiev.ua/rascenki-na-otdelochnye-raboty.html · 800×800 950 грн/м² · Київ · 2026 https://plitka.ua/ua/services/ukladannya-plitki/ · 800х800 900 грн/м² (2025) · Київ · 2025 https://plitochnik.kiev.ua/ua/%D0%B2%D0%B0%D1%80%D1%82%D1%96%D1%81%D1%82%D1%8C-%D1%80%D0%BE%D0%B1%D1%96%D1%82-%D0%BF%D0%BB%D0%B8%D1%82%D0%BE%D1%87%D0%BD%D0%B8%D0%BA%D0%B0.html · середній формат від 816 грн/м² · Київ · 2026
A23: Плитка і підлоги | B23: Плитка | C23: Укладання плитки кабанчик, «цегла» | D23: м² | E23: 998 | F23: 620 | G23: 1297 | H23: 1513 | I23: підняти | J23: 1300 | K23: =IF(AND(ISNUMBER(J23),E23>0),J23/E23-1,"") -> 0.30260521 | N23: =IF(L23="Своя ціна",M23,IF(L23="Прийняти",IF(ISNUMBER(J23),J23,E23),E23)) -> 998 | O23: Одна з найбільших розбіжностей: усі джерела 2026 року дають 1200–1500. | P23: https://www.rabotniki.ua/uk/plitochnye-raboty · «кабанчик» 750/1294/2000 грн/м² · Україна (агрегат) · 2026 https://www.rabotniki.ua/uk/price/ukladka-plitki-na-pol/kiev · «кабанчик» сер. 1334 грн/м² · Київ · 25.10.2026 https://budver.com/masters/ukladannya-plitki-kabanchik · 825/1513/2200 грн/м² · Україна (агрегат) · 2026 https://kabanchik.ua/ua/kyiv/category/ukladannia-plytky · «кабанчик» 1200 грн/м² · Київ · 10.2026 https://stroyremdizayn.kiev.ua/rascenki-na-otdelochnye-raboty.html · «кабанчик» 1300 грн/м² · Київ · 2026 https://plitka.ua/ua/services/ukladannya-plitki/ · кабанчик 620 грн/м² (2025) · Київ · 2025
A24: Плитка і підлоги | B24: Підлоги | C24: Монтаж міжкімнатного порога | D24: м.п. | E24: 400 | F24: 150 | G24: 209 | H24: 215 | I24: знизити | J24: 210 | K24: =IF(AND(ISNUMBER(J24),E24>0),J24/E24-1,"") -> -0.475 | N24: =IF(L24="Своя ціна",M24,IF(L24="Прийняти",IF(ISNUMBER(J24),J24,E24),E24)) -> 400 | O24: Удвічі дорожче за перехідний профіль (200). Для порога краще одиниця PIECE. | P24: https://www.rabotniki.ua/uk/price/ukladka-laminata-price/kiev · прямий поріжок 215 грн/м.п. · Київ · 25.10.2026 https://www.rabotniki.ua/uk/price/tsiklevanie-parketa-pokrytie-lakom · 209 · Україна (агрегат) · 25.10.2026 https://www.remonthub.org/prices.php · порогова планка 150 · Київ · 2026
A25: Плитка і підлоги | B25: Підлоги | C25: Монтаж утеплювача під стяжку | D25: м² | E25: 302 | F25: 130 | G25: 145 | H25: 160 | I25: знизити | J25: 160 | K25: =IF(AND(ISNUMBER(J25),E25>0),J25/E25-1,"") -> -0.47019868 | N25: =IF(L25="Своя ціна",M25,IF(L25="Прийняти",IF(ISNUMBER(J25),J25,E25),E25)) -> 302 | O25: Сусідня позиція 'Монтаж утеплювача' коштує 130, тобто ця завищена. | P25: https://www.rabotniki.ua/uk/chernovye-raboty-po-polu/kiev · утеплення стиродуром 130/160/200 грн/м² · Київ · 2026 https://bud.arsel.com.ua/tsiny-na-budivelni-roboty/ · утеплювач під стяжку 130 · Київ і обл. · 01.01.2026
A26: Плитка і підлоги | B26: Підлоги | C26: Плівкова ізоляція під стяжку | D26: м² | E26: 134 | F26: 60 | G26: 60 | H26: 64 | I26: знизити | J26: 60 | K26: =IF(AND(ISNUMBER(J26),E26>0),J26/E26-1,"") -> -0.55223881 | N26: =IF(L26="Своя ціна",M26,IF(L26="Прийняти",IF(ISNUMBER(J26),J26,E26),E26)) -> 134 | O26: Удвічі вище за ринок. | P26: https://www.rabotniki.ua/uk/chernovye-raboty-po-polu/kiev · плівкова гідроізоляція 40/64/80 грн/м² · Київ · 2026 https://bud.arsel.com.ua/tsiny-na-budivelni-roboty/ · плівкова гідроізоляція 60 · Київ і обл. · 01.01.2026 https://stroyremdizayn.kiev.ua/rascenki-na-otdelochnye-raboty.html · плівка 60 · Київ · 2026
A27: Плитка і підлоги | B27: Підлоги | C27: Укладання фанери або OSB на стяжку чи лаги | D27: м² | E27: 250 | F27: 175 | G27: 202 | H27: 217 | I27: знизити | J27: 210 | K27: =IF(AND(ISNUMBER(J27),E27>0),J27/E27-1,"") -> -0.16 | N27: =IF(L27="Своя ціна",M27,IF(L27="Прийняти",IF(ISNUMBER(J27),J27,E27),E27)) -> 250 | O27: Небагато вище за ринок. | P27: https://www.rabotniki.ua/uk/price/ukladka-laminata-price/kiev · фанера Київ 217 · Київ · 25.10.2026 https://www.rabotniki.ua/uk/price/tsiklevanie-parketa-pokrytie-lakom · фанера Україна 202 · Україна (агрегат) · 25.10.2026 https://rating-remont-kvartir.com.ua/ua/rozcinki-na-roboti-z-pidlogami-lviv/ · фанера на лаги 150–200 (Львів) · Львів · 07.01.2026
A28: Плитка і підлоги | B28: Плитка | C28: Шліфування стяжки (зняття перепадів до 5 мм) | D28: м² | E28: 392 | F28: 180 | G28: 203 | H28: 226 | I28: знизити | J28: 230 | K28: =IF(AND(ISNUMBER(J28),E28>0),J28/E28-1,"") -> -0.41326531 | N28: =IF(L28="Своя ціна",M28,IF(L28="Прийняти",IF(ISNUMBER(J28),J28,E28),E28)) -> 392 | O28: FLOORING 'Шліфування бетонної основи' — 150. | P28: https://www.rabotniki.ua/uk/chernovye-raboty-po-polu/kiev · шліфування стяжки 180/226/280 грн/м² · Київ · 2026 https://plitochnik.kiev.ua/ua/%D0%B2%D0%B0%D1%80%D1%82%D1%96%D1%81%D1%82%D1%8C-%D1%80%D0%BE%D0%B1%D1%96%D1%82-%D0%BF%D0%BB%D0%B8%D1%82%D0%BE%D1%87%D0%BD%D0%B8%D0%BA%D0%B0.html · шліфування, зняття молочка від 180 · Київ · 2026
A29: Плитка і підлоги | B29: Підлоги | C29: Укладання ламінату ялинкою | D29: м² | E29: 500 | F29: 700 | G29: 700 | H29: 700 | I29: неясно | K29: =IF(AND(ISNUMBER(J29),E29>0),J29/E29-1,"") | N29: =IF(L29="Своя ціна",M29,IF(L29="Прийняти",IF(ISNUMBER(J29),J29,E29),E29)) -> 500 | O29: Лише одне джерело (700). Можливо, ціну занижено. | P29: https://parket-doska.com.ua/ukladannya-parketu-iz-zavodskoyu-obrobkoyu-malyunok-francuzka-rizka-ugorska-yalinka-na-styazhku/ · ламінат ялинкою 700 грн/м² · Київ · н/д
A30: Плитка і підлоги | B30: Плитка | C30: Нанесення двокомпонентної гідроізоляції | D30: м² | E30: 273 | F30: 292 | G30: 366 | H30: 440 | I30: неясно | K30: =IF(AND(ISNUMBER(J30),E30>0),J30/E30-1,"") | N30: =IF(L30="Своя ціна",M30,IF(L30="Прийняти",IF(ISNUMBER(J30),J30,E30),E30)) -> 273 | O30: Пряме порівняння є лише одне (PK 440). Схоже, що ціну варто підняти до ~350–400. | P30: https://plitochnik.kiev.ua/ua/%D0%B2%D0%B0%D1%80%D1%82%D1%96%D1%81%D1%82%D1%8C-%D1%80%D0%BE%D0%B1%D1%96%D1%82-%D0%BF%D0%BB%D0%B8%D1%82%D0%BE%D1%87%D0%BD%D0%B8%D0%BA%D0%B0.html · двокомпонентна 2 шари 440 грн/м² · Київ · 2026 https://budver.com/masters/vlashtuvannya-gidroizolyacii-pid-plitkoyu · гідроізоляція під плиткою (тип не вказано) сер. 292 · Україна (агрегат) · 2026
A31: Плитка і підлоги | B31: Підлоги | C31: Армування підлоги сіткою під стяжку | D31: м² | E31: 130 | F31: 85 | G31: 109 | H31: 126 | I31: в ринку | K31: =IF(AND(ISNUMBER(J31),E31>0),J31/E31-1,"") | N31: =IF(L31="Своя ціна",M31,IF(L31="Прийняти",IF(ISNUMBER(J31),J31,E31),E31)) -> 130 | P31: https://www.rabotniki.ua/uk/chernovye-raboty-po-polu/kiev · сітка 100/126/170 грн/м² · Київ · 2026 https://www.rabotniki.ua/uk/chernovye-raboty-po-polu/kiev · армування 113 · Київ · 2026 https://bud.arsel.com.ua/tsiny-na-budivelni-roboty/ · сітка 85 · Київ і обл. · 01.01.2026 https://bud.arsel.com.ua/tsiny-na-budivelni-roboty/ · армування 105 · Київ і обл. · 01.01.2026
A32: Плитка і підлоги | B32: Підлоги | C32: Вирівнювання підлоги самовирівнюючим розчином | D32: м² | E32: 300 | F32: 250 | G32: 300 | H32: 400 | I32: в ринку | K32: =IF(AND(ISNUMBER(J32),E32>0),J32/E32-1,"") | N32: =IF(L32="Своя ціна",M32,IF(L32="Прийняти",IF(ISNUMBER(J32),J32,E32),E32)) -> 300 | O32: Дублі: TILING 'Влаштування наливної підлоги' 255 і FLOORING 'Наливна підлога — вирівнювальний шар 10–50 мм' 279. Усі в межах ринку. | P32: https://www.rabotniki.ua/uk/chernovye-raboty-po-polu/kiev · 180/335/450 грн/м² · Київ · 2026 https://bud.arsel.com.ua/tsiny-na-budivelni-roboty/ · 260 · Київ і обл. · 01.01.2026 https://plitochnik.kiev.ua/ua/%D0%B2%D0%B0%D1%80%D1%82%D1%96%D1%81%D1%82%D1%8C-%D1%80%D0%BE%D0%B1%D1%96%D1%82-%D0%BF%D0%BB%D0%B8%D1%82%D0%BE%D1%87%D0%BD%D0%B8%D0%BA%D0%B0.html · 300 · Київ · 2026 https://mirafloor.com.ua/statti/nalivna-pidloga-tsina-za-m2.html · від 350 (тільки робота) · Київ · 09.2026 https://stroyremdizayn.kiev.ua/rascenki-na-otdelochnye-raboty.html · 250 · Київ · 2026 https://remmo.lviv.ua/plytochni-roboty-lviv/ · 250 · Львів · 25.01.2026 https://www.remonthub.org/prices.php · 400 · Київ · 2026
A33: Плитка і підлоги | B33: Підлоги | C33: Монтаж перехідного (стикового) профілю між покриттями | D33: м.п. | E33: 200 | F33: 150 | G33: 209 | H33: 215 | I33: в ринку | K33: =IF(AND(ISNUMBER(J33),E33>0),J33/E33-1,"") | N33: =IF(L33="Своя ціна",M33,IF(L33="Прийняти",IF(ISNUMBER(J33),J33,E33),E33)) -> 200 | P33: https://www.rabotniki.ua/uk/price/ukladka-laminata-price/kiev · прямий поріжок 215 · Київ · 25.10.2026 https://www.rabotniki.ua/uk/price/tsiklevanie-parketa-pokrytie-lakom · 209 · Україна (агрегат) · 25.10.2026 https://www.remonthub.org/prices.php · порогова планка 150 · Київ · 2026
A34: Плитка і підлоги | B34: Підлоги | C34: Монтаж плінтуса дерев'яного | D34: м.п. | E34: 250 | F34: 175 | G34: 248 | H34: 262 | I34: в ринку | K34: =IF(AND(ISNUMBER(J34),E34>0),J34/E34-1,"") | N34: =IF(L34="Своя ціна",M34,IF(L34="Прийняти",IF(ISNUMBER(J34),J34,E34),E34)) -> 250 | P34: https://www.rabotniki.ua/uk/price/ukladka-laminata-price/kiev · Київ 262 · Київ · 25.10.2026 https://www.rabotniki.ua/uk/price/tsiklevanie-parketa-pokrytie-lakom · 247 · Україна (агрегат) · 25.10.2026 https://stroyremdizayn.kiev.ua/rascenki-na-otdelochnye-raboty.html · 250 · Київ · 2026 https://bud.arsel.com.ua/tsiny-na-budivelni-roboty/ · 175 · Київ і обл. · 01.01.2026
A35: Плитка і підлоги | B35: Підлоги | C35: Монтаж плінтуса пластик | D35: м.п. | E35: 150 | F35: 80 | G35: 135 | H35: 150 | I35: в ринку | K35: =IF(AND(ISNUMBER(J35),E35>0),J35/E35-1,"") | N35: =IF(L35="Своя ціна",M35,IF(L35="Прийняти",IF(ISNUMBER(J35),J35,E35),E35)) -> 150 | P35: https://www.rabotniki.ua/uk/price/ukladka-laminata-price/kiev · Київ 148 · Київ · 25.10.2026 https://www.rabotniki.ua/uk/price/tsiklevanie-parketa-pokrytie-lakom · 140 · Україна (агрегат) · 25.10.2026 https://stroyremdizayn.kiev.ua/rascenki-na-otdelochnye-raboty.html · 150 · Київ · 2026 https://liv-comfort.kyiv.ua/price-remont/index.html · 80 · Київ · 2026 https://bud.arsel.com.ua/tsiny-na-budivelni-roboty/ · 130 · Київ і обл. · 01.01.2026 https://www.remonthub.org/prices.php · 120 · Київ · 2026
A36: Плитка і підлоги | B36: Підлоги | C36: Монтаж плінтуса шпонованого МДФ | D36: м.п. | E36: 280 | F36: 215 | G36: 261 | H36: 280 | I36: в ринку | K36: =IF(AND(ISNUMBER(J36),E36>0),J36/E36-1,"") | N36: =IF(L36="Своя ціна",M36,IF(L36="Прийняти",IF(ISNUMBER(J36),J36,E36),E36)) -> 280 | P36: https://www.rabotniki.ua/uk/price/ukladka-laminata-price/kiev · МДФ Київ 270 · Київ · 25.10.2026 https://www.rabotniki.ua/uk/price/tsiklevanie-parketa-pokrytie-lakom · 261 · Україна (агрегат) · 25.10.2026 https://stroyremdizayn.kiev.ua/rascenki-na-otdelochnye-raboty.html · 280 · Київ · 2026 https://liv-comfort.kyiv.ua/price-remont/index.html · МДФ/поліуретан 250 · Київ · 2026 https://bud.arsel.com.ua/tsiny-na-budivelni-roboty/ · МДФ 215 · Київ і обл. · 01.01.2026
A37: Плитка і підлоги | B37: Підлоги | C37: Настил лінолеуму ковроліну | D37: м² | E37: 200 | F37: 150 | G37: 198 | H37: 250 | I37: в ринку | K37: =IF(AND(ISNUMBER(J37),E37>0),J37/E37-1,"") | N37: =IF(L37="Своя ціна",M37,IF(L37="Прийняти",IF(ISNUMBER(J37),J37,E37),E37)) -> 200 | P37: https://www.rabotniki.ua/uk/price/ukladka-laminata-price/kiev · без клею 207 · Київ · 25.10.2026 https://www.rabotniki.ua/uk/price/tsiklevanie-parketa-pokrytie-lakom · 196 · Україна (агрегат) · 25.10.2026 https://stroyremdizayn.kiev.ua/rascenki-na-otdelochnye-raboty.html · 200 · Київ · 2026 https://liv-comfort.kyiv.ua/price-remont/index.html · 250 · Київ · 2026 https://bud.arsel.com.ua/tsiny-na-budivelni-roboty/ · 150 · Київ і обл. · 01.01.2026 https://www.remonthub.org/prices.php · 190 · Київ · 2026
A38: Плитка і підлоги | B38: Підлоги | C38: Стяжка з керамзитом | D38: м² | E38: 421 | F38: 390 | G38: 423 | H38: 456 | I38: в ринку | K38: =IF(AND(ISNUMBER(J38),E38>0),J38/E38-1,"") | N38: =IF(L38="Своя ціна",M38,IF(L38="Прийняти",IF(ISNUMBER(J38),J38,E38),E38)) -> 421 | P38: https://www.rabotniki.ua/uk/chernovye-raboty-po-polu/kiev · 400/456/500 грн/м² · Київ · 2026 https://bud.arsel.com.ua/tsiny-na-budivelni-roboty/ · 390 · Київ і обл. · 01.01.2026
A39: Плитка і підлоги | B39: Підлоги | C39: Укладання замкового кварцвінілу (SPC) на підкладку | D39: м² | E39: 350 | F39: 350 | G39: 350 | H39: 450 | I39: в ринку | K39: =IF(AND(ISNUMBER(J39),E39>0),J39/E39-1,"") | N39: =IF(L39="Своя ціна",M39,IF(L39="Прийняти",IF(ISNUMBER(J39),J39,E39),E39)) -> 350 | P39: https://stroyremdizayn.kiev.ua/rascenki-na-otdelochnye-raboty.html · на підкладку 350 · Київ · 2026 https://liv-comfort.kyiv.ua/price-remont/index.html · замковий 350 · Київ · 2026 https://parket-doska.com.ua/ukladannya-parketu-iz-zavodskoyu-obrobkoyu-malyunok-francuzka-rizka-ugorska-yalinka-na-styazhku/ · плаваючий 'палуба' 450 · Київ · н/д
A40: Плитка і підлоги | B40: Підлоги | C40: Укладання клейового кварцвінілу (LVT) на клей | D40: м² | E40: 420 | F40: 320 | G40: 410 | H40: 550 | I40: в ринку | K40: =IF(AND(ISNUMBER(J40),E40>0),J40/E40-1,"") | N40: =IF(L40="Своя ціна",M40,IF(L40="Прийняти",IF(ISNUMBER(J40),J40,E40),E40)) -> 420 | P40: https://stroyremdizayn.kiev.ua/rascenki-na-otdelochnye-raboty.html · на клей 420 · Київ · 2026 https://liv-comfort.kyiv.ua/price-remont/index.html · клейовий 400 · Київ · 2026 https://parket-doska.com.ua/ukladannya-parketu-iz-zavodskoyu-obrobkoyu-malyunok-francuzka-rizka-ugorska-yalinka-na-styazhku/ · клейовий 'палуба' 550 · Київ · н/д https://bud.arsel.com.ua/tsiny-na-budivelni-roboty/ · вінілова плитка 320 · Київ і обл. · 01.01.2026
...

Sheet Аномалії
A1: Група | B1: Фах | C1: Позиція | D1: Од. | E1: Наша ціна, ₴ | F1: Що не так | G1: Пропонована ціна, ₴ | H1: Рішення | I1: Коментар
A2: Плитка і підлоги | B2: Плитка | C2: Затирання швів у декоративній плитці, мозаїці | D2: м² | E2: 0 | F2: Ціна 0. Ринок: PK — затирка 180 + доплата за мозаїку 120 = 300 грн/м²; remmo — мозаїка 130 грн/м²; сусідня цементна затирка 116. | G2: 300
A3: Плитка і підлоги | B3: Плитка | C3: Укладання декоративної плитки під «цеглу» або «камінь» (гіпсова, бетонна) | D3: м² | E3: 0 | F3: Ціна 0 (див. checked: ринок ~1000–1100 грн/м²). | G3: 1000
A4: Плитка і підлоги | B4: Плитка | C4: Облицювання плиткою короба | D4: м² | E4: 0 | F4: Ціна 0 і, ймовірно, неправильна одиниця: ринок рахує в м.п. (rabotniki 600/993/1500 грн/м.п.; budver від 660 грн/м.п.). | G4: 900
A5: Плитка і підлоги | B5: Плитка | C5: Гідроізоляція плівкова | D5: м² | E5: 0 | F5: Ціна 0. Ринок 60–64 грн/м² (rabotniki, arsel, stroyremdizayn). | G5: 60
A6: Плитка і підлоги | B6: Плитка | C6: Гідроізоляція сухою сумішшю | D6: м² | E6: 0 | F6: Ціна 0. stroyremdizayn 130 грн/м²; PK цементна 2 шари 264 грн/м²; сусідня мастика 174. | G6: 200
A7: Плитка і підлоги | B7: Плитка | C7: Поклейка гідроізоляційних муфт на водорозетки | D7: шт | E7: 0 | F7: Ціна 0. PK 360 грн/шт; сусідня позиція 'гідроізоляційні кути' 100 грн/шт. | G7: 250
A8: Плитка і підлоги | B8: Плитка | C8: Монтаж трапу та формування ухилу до нього | D8: шт | E8: 0 | F8: Ціна 0 для однієї з ключових позицій ванної. Публічних цін не знайшов; потрібне значення.
A9: Плитка і підлоги | B9: Плитка | C9: Монтаж лінійного душового каналу | D9: шт | E9: 0 | F9: Ціна 0 для ключової позиції. Потрібне значення (зазвичай дорожче за точковий трап).
A10: Плитка і підлоги | B10: Плитка | C10: Влаштування деформаційних швів | D10: м.п. | E10: 0 | F10: Ціна 0. PK: джгут 60 + герметизація 240 грн/м.п.
A11: Плитка і підлоги | B11: Плитка | C11: Укладання плитки поверх теплої підлоги (плюс % до м.кв.) | D11: % | E11: 0 | F11: 0%. Тоді позиція нічого не додає: або видалити, або дати ненульову доплату.
A12: Плитка і підлоги | B12: Плитка | C12: Укладання плитки ялинкою (плюс % до м.кв.) | D12: % | E12: 0 | F12: 0%. PK: діагональ/ялинка від +15%; duflu: ялинка/діагональ у Києві 1100–1800 проти 800–1400 за пряму укладку (≈+30%). Сусідня діагональ +33%. | G12: 30
A13: Плитка і підлоги | B13: Плитка | C13: Укладання плитки на шар клею більше 1 см | D13: м² | E13: 0 | F13: Ціна 0 і одиниця M2 для того, що за змістом є доплатою. stroyremdizayn: +150 грн/м² за товщину понад 1 см; PK: вирівнювання клеєм до 10 мм 264 грн/м². | G13: 150
A14: Плитка і підлоги | B14: Плитка | C14: Винесення та вивезення будівельного сміття | D14: м³ | E14: 0 | F14: TILING 0, а такий самий рядок у FLOORING — 600 грн/м³. | G14: 600
A15: Плитка і підлоги | B15: Плитка | C15: Прибирання приміщення після робіт | D15: м² | E15: 0 | F15: TILING 0, а такий самий рядок у FLOORING — 40 грн/м². | G15: 40
A16: Плитка і підлоги | B16: Плитка | C16: Укриття плівкою підлоги, дверей, сантехніки | D16: м² | E16: 0 | F16: Ціна 0. Сусідні позиції: картон 30, ДВП 70 грн/м². | G16: 30
A17: Плитка і підлоги | B17: Плитка | C17: Виготовлення та монтаж кріплення для раковини (зварювання, фарбування) | D17: шт | E17: 0 | F17: Ціна 0.
A18: Плитка і підлоги | B18: Плитка | C18: Підняття матеріалу по сходах | D18: т | E18: 1642 | F18: Ціна 1642 за тонну не залежить від поверху, хоча сусідній рядок рахується за поверх (FLOOR). Ринок: вантажники ~10–25 ₴ за мішок за поверх.
A19: Плитка і підлоги | B19: Плитка | C19: Розвантаження матеріалу | D19: т | E19: 1271 | F19: PK: 750 ₴/т, наші 1271 ₴/т — помітно вище ринку.
A20: Плитка і підлоги | B20: Плитка | C20: Формування кута з епоксидної суміші | D20: м² | E20: 287 | F20: Одиниця M2 для лінійного елемента. PK: епоксидний зовнішній кут 360 грн/м.п.; plitka.ua: кут епоксидом 300 грн/м.п. Треба LINEAR_METER. | G20: 320
A21: Плитка і підлоги | B21: Плитка | C21: Заміна силіконового шва (видалення старого, нанесення нового) | D21: м.п. | E21: 180 | F21: 180 грн/м.п. — близько до простого заповнення (130), а за ринком (rabotniki 215, PK 240) і нижче за нього. Заміна з видаленням має бути дорожчою. | G21: 280
A22: Плитка і підлоги | B22: Плитка | C22: Сортування плитки та підбір малюнка | D22: м² | E22: 247 | F22: 247 грн/м² завищено: PK — підбір малюнка 60 грн/м² (сортування окремо, 360 грн/год); plitka.ua — підбір малюнка 80 грн/м². | G22: 100
A23: Плитка і підлоги | B23: Плитка | C23: Стяжка маякова цементна | D23: м² | E23: 342 | F23: Різниться з FLOORING 'Цементно-піщана стяжка понад 20м2' (400) / 'до 20м2' (500) за ту саму роботу. | G23: 400
A24: Плитка і підлоги | B24: Плитка | C24: Шліфування стяжки (зняття перепадів до 5 мм) | D24: м² | E24: 392 | F24: 392 проти 150 у FLOORING 'Шліфування бетонної основи' і 161 у 'Шліфування видалення слабкого шару'. Ринок ~226. | G24: 230
A25: Плитка і підлоги | B25: Підлоги | C25: Монтаж демпферної стрічки | D25: м² | E25: 50 | F25: Одиниця M2 для стрічки: має бути LINEAR_METER (або прибрати, бо PK і mirafloor включають стрічку в ціну наливної).
A26: Плитка і підлоги | B26: Підлоги | C26: Приклеювання стиків в місцях порожків, герметизація силіконом | D26: шт | E26: 500 | F26: Дубль позиції 'Приклеювання стиків порожків герметизація' (Плінтус, 212 грн/м.п.), але з одиницею PIECE і ціною 500.
A27: Плитка і підлоги | B27: Підлоги | C27: Монтаж утеплювача під стяжку | D27: м² | E27: 302 | F27: 302 проти 130 у сусідньому 'Монтаж утеплювача'; ринок 130–200. | G27: 160
A28: Плитка і підлоги | B28: Підлоги | C28: Плівкова ізоляція під стяжку | D28: м² | E28: 134 | F28: 134 грн/м² — вдвічі вище за ринок (60–64) і за 'пароізоляційну плівку під ламінат' (30). | G28: 60
A29: Плитка і підлоги | B29: Підлоги | C29: Настил лінолеуму ковроліну на клей | D29: м² | E29: 200 | F29: Дорівнює варіанту без клею (200); на клей має бути дорожче (stroyremdizayn 300, arsel 220). | G29: 260
A30: Плитка і підлоги | B30: Підлоги | C30: Демонтаж лінолеуму ковроліну | D30: м² | E30: 20 | F30: 20 грн/м² — нереально низько (rbk-alba 250, kabanchik 130). | G30: 100
A31: Плитка і підлоги | B31: Підлоги | C31: Демонтаж плінтуса | D31: м.п. | E31: 30 | F31: 30 грн/м.п. — низько: rbk-alba 60 грн/м.п. (дерев'яний/пластиковий). | G31: 60
A32: Плитка і підлоги | B32: Підлоги | C32: Монтаж міжкімнатного порога | D32: м.п. | E32: 400 | F32: 400 грн/м.п. — удвічі більше за перехідний профіль (200); ринок ~210. Поріг зазвичай рахують за шт. | G32: 210
A33: Плитка і підлоги | B33: Плитка | C33: Укладання плитки на відкос (плюс % до м.кв.) | D33: % | E33: 88 | F33: +88% вище за ринкові доплати: plitka.ua +60%; PK — відкос до 600 мм ×0.8 від ціни м² за м.п.; rabotniki — 834 грн/м.п. Варто перевірити. | G33: 60
A34: Малярка і гіпсокартон | B34: Маляр | C34: Штукатурка стін до 2см об'ємом до 50м2 | D34: м² | E34: 280 | F34: Надбавка за малий обсяг має робити ціну вищою за звичайну ручну (330), а тут нижче. Обидві товщини мають однакову ціну 280. Джерело-аналог (stroyremdizayn): 400 (до 2 см) і 430 (від 2 см). | G34: 400
A35: Малярка і гіпсокартон | B35: Маляр | C35: Штукатурка стін від 2см об'ємом до 50м2 | D35: м² | E35: 280 | F35: Те саме: нижче за звичайну ручну від 2 см (380) і дорівнює ціні до 2 см. | G35: 430
A36: Малярка і гіпсокартон | B36: Маляр | C36: Шпаклювання стелі | D36: м² | E36: 270 | F36: Неоднозначна позиція поруч із 'Шпаклівка стелі під фарбування' (420) і 'під склополотно' (360). Якщо це повна підготовка, ціна нижче ринку (kabanchik 350, rabotniki Київ 530). Уточнити обсяг робіт або прибрати дубль.
A37: Малярка і гіпсокартон | B37: Маляр | C37: Акрилення примикань | D37: м.п. | E37: 100 | F37: Та сама робота, що й 'Герметизація швів, стиків акрилом, спеціальною мастикою' (220), але ціни різняться вдвічі. Ринок (rabotniki): герметизація акрилом 80/143/200. | G37: 140
A38: Малярка і гіпсокартон | B38: Маляр | C38: Герметизація швів, стиків акрилом, спеціальною мастикою | D38: м.п. | E38: 220 | F38: Дубль 'Акрилення примикань' (100) з іншою ціною; вище максимуму rabotniki (200). | G38: 140
A39: Малярка і гіпсокартон | B39: Маляр | C39: Відведення лінії фарби довкола вікон/дверей | D39: м² | E39: 100 | F39: Імовірно, неправильна одиниця: лінію рахують у м.п. (пор. 'Розділення кольорів (скотч)' 85 грн/м.п.).
A40: Малярка і гіпсокартон | B40: Маляр | C40: Фарбування нашовної планки | D40: м.п. | E40: 260 | F40: Дорожче за фарбування 1 м² вагонки (220) і вдвічі дорожче за монтаж цієї ж планки (120). Схоже на помилку. | G40: 80
...

Sheet Нові позиції
A1: Група | B1: Фах | C1: Назва | D1: Од. | E1: Ринковий діапазон | F1: Джерела | G1: Додати? | H1: Ціна для каталогу, ₴
A2: Плитка і підлоги | B2: Підлоги | C2: Монтаж електричної теплої підлоги (мат/кабель) | D2: м² | E2: 250–350 грн/м² (remonthub: від 250; Львів 280–350) | F2: https://www.remonthub.org/prices.php https://rating-remont-kvartir.com.ua/ua/rozcinki-na-roboti-z-pidlogami-lviv/
A3: Плитка і підлоги | B3: Підлоги | C3: Підключення теплої підлоги до терморегулятора | D3: шт | E3: ~350 грн/шт | F3: https://www.remonthub.org/prices.php
A4: Плитка і підлоги | B4: Плитка | C4: Облицювання кухонного фартуха плиткою | D4: м² | E4: 700–1050 грн/м² (PK: ×1.1 від базової) | F4: https://liv-comfort.kyiv.ua/price-remont/index.html https://remmo.lviv.ua/plytochni-roboty-lviv/ https://plitochnik.kiev.ua/ua/%D0%B2%D0%B0%D1%80%D1%82%D1%96%D1%81%D1%82%D1%8C-%D1%80%D0%BE%D0%B1%D1%96%D1%82-%D0%BF%D0%BB%D0%B8%D1%82%D0%BE%D1%87%D0%BD%D0%B8%D0%BA%D0%B0.html
A5: Плитка і підлоги | B5: Плитка | C5: Облицювання відкосів/укосів плиткою (за м.п.) | D5: м.п. | E5: 500–1300 грн/м.п. (rabotniki сер. 834; remonthub 500; remmo 650; budver від 528) | F5: https://www.rabotniki.ua/uk/plitochnye-raboty https://www.remonthub.org/prices.php https://remmo.lviv.ua/plytochni-roboty-lviv/ https://budver.com/masters/plitochni-roboti
A6: Плитка і підлоги | B6: Підлоги | C6: Демонтаж ламінату | D6: м² | E6: 130–160 грн/м² | F6: https://rbk-alba.com/ua/price https://kabanchik.ua/ua/kyiv/category/ukladannia-laminatu
A7: Плитка і підлоги | B7: Підлоги | C7: Демонтаж паркету / дерев'яної підлоги | D7: м² | E7: 100–200 грн/м² | F7: https://rbk-alba.com/ua/price https://rating-remont-kvartir.com.ua/ua/rozcinki-na-roboti-z-pidlogami-lviv/
A8: Плитка і підлоги | B8: Підлоги | C8: Демонтаж ПВХ-плитки / кварцвінілу | D8: м² | E8: ~250 грн/м² | F8: https://rbk-alba.com/ua/price
A9: Плитка і підлоги | B9: Плитка | C9: Демонтаж керамічного плінтуса | D9: м.п. | E9: ~260 грн/м.п. | F9: https://rbk-alba.com/ua/price
A10: Плитка і підлоги | B10: Підлоги | C10: Встановлення маяків для стяжки | D10: м² | E10: 85–130 грн/м² (rabotniki 104/122/130; arsel 85) | F10: https://www.rabotniki.ua/uk/chernovye-raboty-po-polu/kiev https://bud.arsel.com.ua/tsiny-na-budivelni-roboty/
A11: Плитка і підлоги | B11: Підлоги | C11: Стяжка з пінополістиролбетону | D11: м² | E11: 305–500 грн/м² (rabotniki 390/448/500; arsel 305) | F11: https://www.rabotniki.ua/uk/chernovye-raboty-po-polu/kiev https://bud.arsel.com.ua/tsiny-na-budivelni-roboty/
A12: Плитка і підлоги | B12: Підлоги | C12: Укладання кварцвінілу ялинкою | D12: м² | E12: ~700 грн/м² | F12: https://parket-doska.com.ua/ukladannya-parketu-iz-zavodskoyu-obrobkoyu-malyunok-francuzka-rizka-ugorska-yalinka-na-styazhku/
A13: Плитка і підлоги | B13: Підлоги | C13: Радіусна (фігурна) підрізка ламінату | D13: м.п. | E13: ~150 грн/м.п. | F13: https://www.remonthub.org/prices.php
... A64: Будівельник, демонтаж, метал | B64: Метал | C64: Зварювальний шов (за м.п.: MMA / напівавтомат / аргон) | D64: м.п. | E64: від 100 / від 120 / від 200 (rating-remont); 258–541 за м.п. при кромці 4–6 мм (duga.in.ua); труби d21–d42 250–400 (kabanchik) | F64: https://rating-remont-kvartir.com.ua/ua/rozcinki-na-zvarjuvalni-roboti/ https://duga.in.ua/ua/prajs2.html https://kabanchik.ua/ua/kyiv/tag/posluhy-zvariuvalnyka

Sheet Джерела
A1: Джерело | B1: Що там є | C1: Актуальність | D1: Якість | E1: Нове (не було у попередніх рев'ю) | F1: Групи, де використано
A2: rabotniki.ua | B2: Мін/сер/макс за десятками позицій, окремо Київ і Львів: кладка, фасад, покрівля, бетон, фундамент, тротуарна плитка, монтаж ФБС/армопояс, демонтаж (стіни, підлога, вікна/двері, отвори), вивіз/винос сміття, вантажники, паркани, ворота/хвіртки, сходи, навіси, ковка, демонтаж/зварювання металоконструкцій | C2: 2026-10 | D2: добре | E2: ні | F2: Плитка і підлоги, Малярка і гіпсокартон, Електрика, Сантехніка, Будівельник, демонтаж, метал
A3: bud.arsel.com.ua | B3: Київ: демонтаж (перегородки, стяжка, плитка, двері, вікна, отвори), фасад/вентфасад 'від', покрівля 'від' | C3: 2026-01 | D3: добре | E3: так | F3: Плитка і підлоги, Малярка і гіпсокартон, Електрика, Сантехніка, Будівельник, демонтаж, метал
A4: rbk-alba.com | B4: Великий київський прайс (~250 позицій демонтажу + кам'яні та бетонні роботи); дата оновлення 19.10.2026; демонтаж помітно вище бюджетного сегменту | C4: 2026-10 | D4: добре | E4: так | F4: Плитка і підлоги, Малярка і гіпсокартон, Електрика, Сантехніка, Будівельник, демонтаж, метал
A5: plitochnik.kiev.ua | B5: Детальний прайс плиткової бригади з Києва (формати, 45°, отвори, затирки, гідроізоляція, вироби), окрема сторінка для широкоформатного керамограніту. Структура дуже схожа на наш каталог | C5: 2026 | D5: добре | E5: так | F5: Плитка і підлоги
A6: amperage.com.ua | B6: Прайс електромонтажної компанії зі Львова: ~70 позицій (щит за модулями, автомати за полюсами, ПЗВ 2/4п, перемикачі аварійного живлення, трек, LED, точкові з отворами). | C6: 2026 (стор. змінено 05.2026) | D6: добре | E6: так | F6: Електрика
A7: altek.kiev.ua | B7: Прайс електрика з Києва 2026: коробки за матеріалами, штроба з закладенням, плита/духовка, бойлер, реле, інвертор, генератор, виїзд, години, надбавки +30%. | C7: 2026 | D7: добре | E7: так | F7: Електрика
A8: pilo-material.kiev.ua | B8: Київський прайс покрівельних робіт, явно 'тільки робота' (металочерепиця, профнастил, бітумна, крокви, обрешітка, утеплення, водостоки) | C8: 2026-10 | D8: добре | E8: так | F8: Будівельник, демонтаж, метал
A9: pl2t.com | B9: Київ: детальний прайс укладання тротуарної плитки, бордюрів, гарцовки, основи, люків/піскоприймачів | C9: 2026-07 | D9: добре | E9: так | F9: Будівельник, демонтаж, метал
A10: budver.com | B10: Маркетплейс майстрів: ціни 'від' і мін/сер/макс (затирка, епоксидка, гідроізоляція, 45°, кабанчик). Схоже на шаблон (та сама кількість майстрів 1119, макс = 2,5–3×мін) | C10: 2026 | D10: нормально | E10: ні | F10: Плитка і підлоги, Малярка і гіпсокартон, Електрика, Сантехніка, Будівельник, демонтаж, метал
A11: kabanchik.ua | B11: Категорія «Електрик» Київ: блоки «від» (стабілізатор, лічильник, щит, домофон, люстри) і фіксований блок «Вартість послуг»; також «Інші послуги електрика» і «Установка духової шафи». Ціни «від» місцями і завищені, і занижені, тож бралися обережно. | C11: 2026-10 | D11: нормально | E11: ні | F11: Плитка і підлоги, Малярка і гіпсокартон, Електрика, Сантехніка, Будівельник, демонтаж, метал
A12: remonthub.org | B12: Київський прайс-лист 2026: плитка, затирки, гідроізоляція, стяжка, ламінат, тепла підлога | C12: 2026 | D12: нормально | E12: так | F12: Плитка і підлоги, Малярка і гіпсокартон, Електрика, Сантехніка, Будівельник, демонтаж, метал
... A39: ecowood.com.ua | B39: Тераси: металокаркас із профтруби 1800 грн/м², 'Стандартна тераса' 5300 грн/м² (неясно чи з матеріалом) | C39: н/д | D39: слабко | E39: так | F39: Будівельник, демонтаж, метал
